Workbook

Sheet Xülasə
A1: Bitirmə layihəsi — Test case-lər
A2: Tamara Məlikova · turbo.az (Web UI) + Banking API (https://api.anarabbas.com)
A4: Hissə | B4: Test case | C4: Automation | D4: Manual | E4: Regression | F4: PASS ✓ | G4: FAIL ✗ | H4: Blocked | I4: Not Run
A5: Web — turbo.az | B5: =COUNTA('Web Test Cases'!A:A)-1 -> 128 | C5: =COUNTIF('Web Test Cases'!M:M,"Automation") -> 29 | D5: =COUNTIF('Web Test Cases'!M:M,"Manual") -> 99 | E5: =COUNTIF('Web Test Cases'!N:N,"Yes") -> 35 | F5: =COUNTIF('Web Test Cases'!K:K,"PASS ✓") -> 126 | G5: =COUNTIF('Web Test Cases'!K:K,"FAIL ✗") -> 2 | H5: =COUNTIF('Web Test Cases'!K:K,"Blocked") -> 0 | I5: =COUNTIF('Web Test Cases'!K:K,"Not Run") -> 0
A6: API — GRAD-101…303 | B6: =COUNTA('API Test Cases'!A:A)-1 -> 169 | C6: =COUNTIF('API Test Cases'!M:M,"Automation") -> 156 | D6: =COUNTIF('API Test Cases'!M:M,"Manual") -> 13 | E6: =COUNTIF('API Test Cases'!N:N,"Yes") -> 156 | F6: =COUNTIF('API Test Cases'!K:K,"PASS ✓") -> 168 | G6: =COUNTIF('API Test Cases'!K:K,"FAIL ✗") -> 0 | H6: =COUNTIF('API Test Cases'!K:K,"Blocked") -> 1 | I6: =COUNTIF('API Test Cases'!K:K,"Not Run") -> 0
A7: Cəmi | B7: =SUM(B5:B6) -> 297 | C7: =SUM(C5:C6) -> 185 | D7: =SUM(D5:D6) -> 112 | E7: =SUM(E5:E6) -> 191 | F7: =SUM(F5:F6) -> 294 | G7: =SUM(G5:G6) -> 2 | H7: =SUM(H5:H6) -> 1 | I7: =SUM(I5:I6) -> 0
A9: Sheet-lər
A10: Web Test Cases | B10: turbo.az test case-ləri (Execution Type, Regression, Manual/Automation əsaslandırması ilə)
A11: Web Test Scenarios | B11: 13 test ssenarisi və onlara bağlı test case sayları
A12: Web Test Scope | B12: Scope daxili / xarici və fərziyyələr
A13: Tapıntılar | B13: Manual və avtomat icra zamanı tapılan bug-lar və uyğunsuzluqlar (əlaqəli test case ilə)
A14: API Test Cases | B14: API test case-ləri, AC Reference sütunu ilə
A15: API Coverage | B15: Task üzrə AC, test case, avtomat / manual sayları
A16: API Traceability | B16: Hər acceptance criterion → test case-lər (69 AC-nin hamısı əhatə olunub)
A17: API Grooming Questions | B17: Backlog-dakı qaranlıq və ziddiyyətli yerlər üzrə suallar
A19: İcra qeydləri
A20: Avtomat icra | B20: 12.10.2026, Gauge HTML hesabatı. API paketi ardıcıl 3 icrada stabil (161 ssenari, 0 düşən). Web paketi 29/29 keçdi
A21: CallMan icrası | B21: 12.10.2026: kolleksiyanın 75 avtomat yoxlaması keçdi (failures = []); manual müşahidələr Actual Result sütununa yazılıb
A22: Mühit müşahidəsi | B22: turbo.az bəzən səhifəni 3 dəqiqədən çox yükləyir (reklam bannerləri). Bu halda test TimeoutException ilə düşür və təkrar icrada keçir — test xətası deyil
A23: Manual test case-lər | B23: Actual Result və Status sütunları manual icradan sonra doldurulur (Status: PASS ✓ / FAIL ✗ / Blocked)
A25: Test Report | B25: İcra nəticələri, qrafiklər, modul/task bölgüsü, avtomat icraların stabilliyi, tapıntılar və nəticə

Sheet Test Report
B2: Test Report — Bitirmə layihəsi
B3: turbo.az (Web UI) + Banking API (https://api.anarabbas.com) · Hazırladı: Tamara Məlikova · Hesabat tarixi: 09.10.2026
B4: Bu sheet test case sheet-lərindən formullarla hesablanır: Status dəyişəndə bütün rəqəmlər və qrafiklər avtomatik yenilənir.
B6: Əsas göstəricilər
B8: Ümumi | C8: Test case | D8: İcra olunub | E8: Keçdi (PASS) | F8: Keçmə faizi | G8: Avtomatlaşdırma | H8: Tapıntılar | I8: Blocked | J8: Not Run
B9: Web + API | C9: =COUNTA('Web Test Cases'!A:A)-1+COUNTA('API Test Cases'!A:A)-1 -> 297 | D9: =C9-COUNTIF('Web Test Cases'!K:K,"Not Run")-COUNTIF('API Test Cases'!K:K,"Not Run")-COUNTIF('Web Test Cases'!K:K,"Blocked")-COUNTIF('API Test Cases'!K:K,"Blocked") -> 296 | E9: =COUNTIF('Web Test Cases'!K:K,"PASS ✓")+COUNTIF('API Test Cases'!K:K,"PASS ✓") -> 294 | F9: =IFERROR(E9/D9,0) -> 0.99324324 | G9: =IFERROR((COUNTIF('Web Test Cases'!M:M,"Automation")+COUNTIF('API Test Cases'!M:M,"Automation"))/C9,0) -> 0.62289562 | H9: =COUNTA(Tapıntılar!A:A)-1 -> 3 | I9: =COUNTIF('Web Test Cases'!K:K,"Blocked")+COUNTIF('API Test Cases'!K:K,"Blocked") -> 1 | J9: =COUNTIF('Web Test Cases'!K:K,"Not Run")+COUNTIF('API Test Cases'!K:K,"Not Run") -> 0
B11: 1. İcra nəticələri
B12: Hissə | C12: Test case | D12: PASS ✓ | E12: FAIL ✗ | F12: Blocked | G12: Not Run | H12: İcra olunub | I12: Keçmə faizi | J12: Avtomat | K12: Manual
B13: Web — turbo.az | C13: =COUNTA('Web Test Cases'!A:A)-1 -> 128 | D13: =COUNTIF('Web Test Cases'!K:K,"PASS ✓") -> 126 | E13: =COUNTIF('Web Test Cases'!K:K,"FAIL ✗") -> 2 | F13: =COUNTIF('Web Test Cases'!K:K,"Blocked") -> 0 | G13: =COUNTIF('Web Test Cases'!K:K,"Not Run") -> 0 | H13: =D13+E13 -> 128 | I13: =IFERROR(D13/H13,0) -> 0.984375 | J13: =COUNTIF('Web Test Cases'!M:M,"Automation") -> 29 | K13: =COUNTIF('Web Test Cases'!M:M,"Manual") -> 99 | M13: Avtomat | N13: =J15 -> 185
B14: API — GRAD-101…303 | C14: =COUNTA('API Test Cases'!A:A)-1 -> 169 | D14: =COUNTIF('API Test Cases'!K:K,"PASS ✓") -> 168 | E14: =COUNTIF('API Test Cases'!K:K,"FAIL ✗") -> 0 | F14: =COUNTIF('API Test Cases'!K:K,"Blocked") -> 1 | G14: =COUNTIF('API Test Cases'!K:K,"Not Run") -> 0 | H14: =D14+E14 -> 168 | I14: =IFERROR(D14/H14,0) -> 1 | J14: =COUNTIF('API Test Cases'!M:M,"Automation") -> 156 | K14: =COUNTIF('API Test Cases'!M:M,"Manual") -> 13 | M14: Manual | N14: =K15 -> 112
B15: Cəmi | C15: =SUM(C13:C14) -> 297 | D15: =SUM(D13:D14) -> 294 | E15: =SUM(E13:E14) -> 2 | F15: =SUM(F13:F14) -> 1 | G15: =SUM(G13:G14) -> 0 | H15: =SUM(H13:H14) -> 296 | I15: =IFERROR(D15/H15,0) -> 0.99324324 | J15: =SUM(J13:J14) -> 185 | K15: =SUM(K13:K14) -> 112
B16: Keçmə faizi = PASS / (PASS + FAIL). Blocked və Not Run icra olunmuş sayılmır.
B33: 2. Web (turbo.az) — modullar üzrə
B34: Modul | C34: Test case | D34: Avtomat | E34: Manual | F34: PASS ✓ | G34: FAIL ✗ | H34: Blocked | I34: Keçmə faizi | J34: Regression
B35: Əsas axtarış | C35: =COUNTIF('Web Test Cases'!C:C,"Əsas axtarış") -> 14 | D35: =COUNTIFS('Web Test Cases'!C:C,"Əsas axtarış",'Web Test Cases'!M:M,"Automation") -> 9 | E35: =COUNTIFS('Web Test Cases'!C:C,"Əsas axtarış",'Web Test Cases'!M:M,"Manual") -> 5 | F35: =COUNTIFS('Web Test Cases'!C:C,"Əsas axtarış",'Web Test Cases'!K:K,"PASS ✓") -> 14 | G35: =COUNTIFS('Web Test Cases'!C:C,"Əsas axtarış",'Web Test Cases'!K:K,"FAIL ✗") -> 0 | H35: =COUNTIFS('Web Test Cases'!C:C,"Əsas axtarış",'Web Test Cases'!K:K,"Blocked") -> 0 | I35: =IFERROR(F35/(F35+G35),0) -> 1 | J35: =COUNTIFS('Web Test Cases'!C:C,"Əsas axtarış",'Web Test Cases'!N:N,"Yes") -> 9
B36: Qiymət filtri | C36: =COUNTIF('Web Test Cases'!C:C,"Qiymət filtri") -> 13 | D36: =COUNTIFS('Web Test Cases'!C:C,"Qiymət filtri",'Web Test Cases'!M:M,"Automation") -> 4 | E36: =COUNTIFS('Web Test Cases'!C:C,"Qiymət filtri",'Web Test Cases'!M:M,"Manual") -> 9 | F36: =COUNTIFS('Web Test Cases'!C:C,"Qiymət filtri",'Web Test Cases'!K:K,"PASS ✓") -> 13 | G36: =COUNTIFS('Web Test Cases'!C:C,"Qiymət filtri",'Web Test Cases'!K:K,"FAIL ✗") -> 0 | H36: =COUNTIFS('Web Test Cases'!C:C,"Qiymət filtri",'Web Test Cases'!K:K,"Blocked") -> 0 | I36: =IFERROR(F36/(F36+G36),0) -> 1 | J36: =COUNTIFS('Web Test Cases'!C:C,"Qiymət filtri",'Web Test Cases'!N:N,"Yes") -> 4
B37: Buraxılış ili filtri | C37: =COUNTIF('Web Test Cases'!C:C,"Buraxılış ili filtri") -> 8 | D37: =COUNTIFS('Web Test Cases'!C:C,"Buraxılış ili filtri",'Web Test Cases'!M:M,"Automation") -> 1 | E37: =COUNTIFS('Web Test Cases'!C:C,"Buraxılış ili filtri",'Web Test Cases'!M:M,"Manual") -> 7 | F37: =COUNTIFS('Web Test Cases'!C:C,"Buraxılış ili filtri",'Web Test Cases'!K:K,"PASS ✓") -> 8 | G37: =COUNTIFS('Web Test Cases'!C:C,"Buraxılış ili filtri",'Web Test Cases'!K:K,"FAIL ✗") -> 0 | H37: =COUNTIFS('Web Test Cases'!C:C,"Buraxılış ili filtri",'Web Test Cases'!K:K,"Blocked") -> 0 | I37: =IFERROR(F37/(F37+G37),0) -> 1 | J37: =COUNTIFS('Web Test Cases'!C:C,"Buraxılış ili filtri",'Web Test Cases'!N:N,"Yes") -> 1
B38: Əlavə filtrlər | C38: =COUNTIF('Web Test Cases'!C:C,"Əlavə filtrlər") -> 25 | D38: =COUNTIFS('Web Test Cases'!C:C,"Əlavə filtrlər",'Web Test Cases'!M:M,"Automation") -> 4 | E38: =COUNTIFS('Web Test Cases'!C:C,"Əlavə filtrlər",'Web Test Cases'!M:M,"Manual") -> 21 | F38: =COUNTIFS('Web Test Cases'!C:C,"Əlavə filtrlər",'Web Test Cases'!K:K,"PASS ✓") -> 24 | G38: =COUNTIFS('Web Test Cases'!C:C,"Əlavə filtrlər",'Web Test Cases'!K:K,"FAIL ✗") -> 1 | H38: =COUNTIFS('Web Test Cases'!C:C,"Əlavə filtrlər",'Web Test Cases'!K:K,"Blocked") -> 0 | I38: =IFERROR(F38/(F38+G38),0) -> 0.96 | J38: =COUNTIFS('Web Test Cases'!C:C,"Əlavə filtrlər",'Web Test Cases'!N:N,"Yes") -> 4
B39: Sıralama | C39: =COUNTIF('Web Test Cases'!C:C,"Sıralama") -> 7 | D39: =COUNTIFS('Web Test Cases'!C:C,"Sıralama",'Web Test Cases'!M:M,"Automation") -> 3 | E39: =COUNTIFS('Web Test Cases'!C:C,"Sıralama",'Web Test Cases'!M:M,"Manual") -> 4 | F39: =COUNTIFS('Web Test Cases'!C:C,"Sıralama",'Web Test Cases'!K:K,"PASS ✓") -> 7 | G39: =COUNTIFS('Web Test Cases'!C:C,"Sıralama",'Web Test Cases'!K:K,"FAIL ✗") -> 0 | H39: =COUNTIFS('Web Test Cases'!C:C,"Sıralama",'Web Test Cases'!K:K,"Blocked") -> 0 | I39: =IFERROR(F39/(F39+G39),0) -> 1 | J39: =COUNTIFS('Web Test Cases'!C:C,"Sıralama",'Web Test Cases'!N:N,"Yes") -> 3
B40: Səhifələmə | C40: =COUNTIF('Web Test Cases'!C:C,"Səhifələmə") -> 7 | D40: =COUNTIFS('Web Test Cases'!C:C,"Səhifələmə",'Web Test Cases'!M:M,"Automation") -> 1 | E40: =COUNTIFS('Web Test Cases'!C:C,"Səhifələmə",'Web Test Cases'!M:M,"Manual") -> 6 | F40: =COUNTIFS('Web Test Cases'!C:C,"Səhifələmə",'Web Test Cases'!K:K,"PASS ✓") -> 7 | G40: =COUNTIFS('Web Test Cases'!C:C,"Səhifələmə",'Web Test Cases'!K:K,"FAIL ✗") -> 0 | H40: =COUNTIFS('Web Test Cases'!C:C,"Səhifələmə",'Web Test Cases'!K:K,"Blocked") -> 0 | I40: =IFERROR(F40/(F40+G40),0) -> 1 | J40: =COUNTIFS('Web Test Cases'!C:C,"Səhifələmə",'Web Test Cases'!N:N,"Yes") -> 1
B41: Elan səhifəsi | C41: =COUNTIF('Web Test Cases'!C:C,"Elan səhifəsi") -> 10 | D41: =COUNTIFS('Web Test Cases'!C:C,"Elan səhifəsi",'Web Test Cases'!M:M,"Automation") -> 3 | E41: =COUNTIFS('Web Test Cases'!C:C,"Elan səhifəsi",'Web Test Cases'!M:M,"Manual") -> 7 | F41: =COUNTIFS('Web Test Cases'!C:C,"Elan səhifəsi",'Web Test Cases'!K:K,"PASS ✓") -> 10 | G41: =COUNTIFS('Web Test Cases'!C:C,"Elan səhifəsi",'Web Test Cases'!K:K,"FAIL ✗") -> 0 | H41: =COUNTIFS('Web Test Cases'!C:C,"Elan səhifəsi",'Web Test Cases'!K:K,"Blocked") -> 0 | I41: =IFERROR(F41/(F41+G41),0) -> 1 | J41: =COUNTIFS('Web Test Cases'!C:C,"Elan səhifəsi",'Web Test Cases'!N:N,"Yes") -> 4
B42: Seçilmişlər | C42: =COUNTIF('Web Test Cases'!C:C,"Seçilmişlər") -> 4 | D42: =COUNTIFS('Web Test Cases'!C:C,"Seçilmişlər",'Web Test Cases'!M:M,"Automation") -> 2 | E42: =COUNTIFS('Web Test Cases'!C:C,"Seçilmişlər",'Web Test Cases'!M:M,"Manual") -> 2 | F42: =COUNTIFS('Web Test Cases'!C:C,"Seçilmişlər",'Web Test Cases'!K:K,"PASS ✓") -> 4 | G42: =COUNTIFS('Web Test Cases'!C:C,"Seçilmişlər",'Web Test Cases'!K:K,"FAIL ✗") -> 0 | H42: =COUNTIFS('Web Test Cases'!C:C,"Seçilmişlər",'Web Test Cases'!K:K,"Blocked") -> 0 | I42: =IFERROR(F42/(F42+G42),0) -> 1 | J42: =COUNTIFS('Web Test Cases'!C:C,"Seçilmişlər",'Web Test Cases'!N:N,"Yes") -> 2
B43: Dil və naviqasiya | C43: =COUNTIF('Web Test Cases'!C:C,"Dil və naviqasiya") -> 9 | D43: =COUNTIFS('Web Test Cases'!C:C,"Dil və naviqasiya",'Web Test Cases'!M:M,"Automation") -> 2 | E43: =COUNTIFS('Web Test Cases'!C:C,"Dil və naviqasiya",'Web Test Cases'!M:M,"Manual") -> 7 | F43: =COUNTIFS('Web Test Cases'!C:C,"Dil və naviqasiya",'Web Test Cases'!K:K,"PASS ✓") -> 9 | G43: =COUNTIFS('Web Test Cases'!C:C,"Dil və naviqasiya",'Web Test Cases'!K:K,"FAIL ✗") -> 0 | H43: =COUNTIFS('Web Test Cases'!C:C,"Dil və naviqasiya",'Web Test Cases'!K:K,"Blocked") -> 0 | I43: =IFERROR(F43/(F43+G43),0) -> 1 | J43: =COUNTIFS('Web Test Cases'!C:C,"Dil və naviqasiya",'Web Test Cases'!N:N,"Yes") -> 2
B44: Giriş (Autentifikasiya) | C44: =COUNTIF('Web Test Cases'!C:C,"Giriş (Autentifikasiya)") -> 12 | D44: =COUNTIFS('Web Test Cases'!C:C,"Giriş (Autentifikasiya)",'Web Test Cases'!M:M,"Automation") -> 0 | E44: =COUNTIFS('Web Test Cases'!C:C,"Giriş (Autentifikasiya)",'Web Test Cases'!M:M,"Manual") -> 12 | F44: =COUNTIFS('Web Test Cases'!C:C,"Giriş (Autentifikasiya)",'Web Test Cases'!K:K,"PASS ✓") -> 12 | G44: =COUNTIFS('Web Test Cases'!C:C,"Giriş (Autentifikasiya)",'Web Test Cases'!K:K,"FAIL ✗") -> 0 | H44: =COUNTIFS('Web Test Cases'!C:C,"Giriş (Autentifikasiya)",'Web Test Cases'!K:K,"Blocked") -> 0 | I44: =IFERROR(F44/(F44+G44),0) -> 1 | J44: =COUNTIFS('Web Test Cases'!C:C,"Giriş (Autentifikasiya)",'Web Test Cases'!N:N,"Yes") -> 3
B45: Yeni elan | C45: =COUNTIF('Web Test Cases'!C:C,"Yeni elan") -> 12 | D45: =COUNTIFS('Web Test Cases'!C:C,"Yeni elan",'Web Test Cases'!M:M,"Automation") -> 0 | E45: =COUNTIFS('Web Test Cases'!C:C,"Yeni elan",'Web Test Cases'!M:M,"Manual") -> 12 | F45: =COUNTIFS('Web Test Cases'!C:C,"Yeni elan",'Web Test Cases'!K:K,"PASS ✓") -> 11 | G45: =COUNTIFS('Web Test Cases'!C:C,"Yeni elan",'Web Test Cases'!K:K,"FAIL ✗") -> 1 | H45: =COUNTIFS('Web Test Cases'!C:C,"Yeni elan",'Web Test Cases'!K:K,"Blocked") -> 0 | I45: =IFERROR(F45/(F45+G45),0) -> 0.91666667 | J45: =COUNTIFS('Web Test Cases'!C:C,"Yeni elan",'Web Test Cases'!N:N,"Yes") -> 2
B46: Ödənişli xidmətlər | C46: =COUNTIF('Web Test Cases'!C:C,"Ödənişli xidmətlər") -> 1 | D46: =COUNTIFS('Web Test Cases'!C:C,"Ödənişli xidmətlər",'Web Test Cases'!M:M,"Automation") -> 0 | E46: =COUNTIFS('Web Test Cases'!C:C,"Ödənişli xidmətlər",'Web Test Cases'!M:M,"Manual") -> 1 | F46: =COUNTIFS('Web Test Cases'!C:C,"Ödənişli xidmətlər",'Web Test Cases'!K:K,"PASS ✓") -> 1 | G46: =COUNTIFS('Web Test Cases'!C:C,"Ödənişli xidmətlər",'Web Test Cases'!K:K,"FAIL ✗") -> 0 | H46: =COUNTIFS('Web Test Cases'!C:C,"Ödənişli xidmətlər",'Web Test Cases'!K:K,"Blocked") -> 0 | I46: =IFERROR(F46/(F46+G46),0) -> 1 | J46: =COUNTIFS('Web Test Cases'!C:C,"Ödənişli xidmətlər",'Web Test Cases'!N:N,"Yes") -> 0
B47: UI/UX | C47: =COUNTIF('Web Test Cases'!C:C,"UI/UX") -> 6 | D47: =COUNTIFS('Web Test Cases'!C:C,"UI/UX",'Web Test Cases'!M:M,"Automation") -> 0 | E47: =COUNTIFS('Web Test Cases'!C:C,"UI/UX",'Web Test Cases'!M:M,"Manual") -> 6 | F47: =COUNTIFS('Web Test Cases'!C:C,"UI/UX",'Web Test Cases'!K:K,"PASS ✓") -> 6 | G47: =COUNTIFS('Web Test Cases'!C:C,"UI/UX",'Web Test Cases'!K:K,"FAIL ✗") -> 0 | H47: =COUNTIFS('Web Test Cases'!C:C,"UI/UX",'Web Test Cases'!K:K,"Blocked") -> 0 | I47: =IFERROR(F47/(F47+G47),0) -> 1 | J47: =COUNTIFS('Web Test Cases'!C:C,"UI/UX",'Web Test Cases'!N:N,"Yes") -> 0
B48: Cəmi | C48: =SUM(C35:C47) -> 128 | D48: =SUM(D35:D47) -> 29 | E48: =SUM(E35:E47) -> 99 | F48: =SUM(F35:F47) -> 126 | G48: =SUM(G35:G47) -> 2 | H48: =SUM(H35:H47) -> 0 | I48: =IFERROR(F48/(F48+G48),0) -> 0.984375 | J48: =SUM(J35:J47) -> 35
B51: 3. API — task-lar üzrə
B52: Task | C52: Test case | D52: Avtomat | E52: Manual | F52: PASS ✓ | G52: FAIL ✗ | H52: Blocked | I52: Keçmə faizi | J52: Highest / High | M52: Qısa ad
B53: GRAD-101 · POST /beneficiaries | C53: =COUNTIF('API Test Cases'!C:C,"GRAD-101 · POST /beneficiaries") -> 31 | D53: =COUNTIFS('API Test Cases'!C:C,"GRAD-101 · POST /beneficiaries",'API Test Cases'!M:M,"Automation") -> 30 | E53: =COUNTIFS('API Test Cases'!C:C,"GRAD-101 · POST /beneficiaries",'API Test Cases'!M:M,"Manual") -> 1 | F53: =COUNTIFS('API Test Cases'!C:C,"GRAD-101 · POST /beneficiaries",'API Test Cases'!K:K,"PASS ✓") -> 31 | G53: =COUNTIFS('API Test Cases'!C:C,"GRAD-101 · POST /beneficiaries",'API Test Cases'!K:K,"FAIL ✗") -> 0 | H53: =COUNTIFS('API Test Cases'!C:C,"GRAD-101 · POST /beneficiaries",'API Test Cases'!K:K,"Blocked") -> 0 | I53: =IFERROR(F53/(F53+G53),0) -> 1 | J53: =COUNTIFS('API Test Cases'!C:C,"GRAD-101 · POST /beneficiaries",'API Test Cases'!D:D,"Highest")+COUNTIFS('API Test Cases'!C:C,"GRAD-101 · POST /beneficiaries",'API Test Cases'!D:D,"High") -> 15 | M53: GRAD-101
B54: GRAD-102 · GET /beneficiaries | C54: =COUNTIF('API Test Cases'!C:C,"GRAD-102 · GET /beneficiaries") -> 15 | D54: =COUNTIFS('API Test Cases'!C:C,"GRAD-102 · GET /beneficiaries",'API Test Cases'!M:M,"Automation") -> 15 | E54: =COUNTIFS('API Test Cases'!C:C,"GRAD-102 · GET /beneficiaries",'API Test Cases'!M:M,"Manual") -> 0 | F54: =COUNTIFS('API Test Cases'!C:C,"GRAD-102 · GET /beneficiaries",'API Test Cases'!K:K,"PASS ✓") -> 15 | G54: =COUNTIFS('API Test Cases'!C:C,"GRAD-102 · GET /beneficiaries",'API Test Cases'!K:K,"FAIL ✗") -> 0 | H54: =COUNTIFS('API Test Cases'!C:C,"GRAD-102 · GET /beneficiaries",'API Test Cases'!K:K,"Blocked") -> 0 | I54: =IFERROR(F54/(F54+G54),0) -> 1 | J54: =COUNTIFS('API Test Cases'!C:C,"GRAD-102 · GET /beneficiaries",'API Test Cases'!D:D,"Highest")+COUNTIFS('API Test Cases'!C:C,"GRAD-102 · GET /beneficiaries",'API Test Cases'!D:D,"High") -> 2 | M54: GRAD-102
B55: GRAD-103 · DELETE /beneficiaries/{id} | C55: =COUNTIF('API Test Cases'!C:C,"GRAD-103 · DELETE /beneficiaries/{id}") -> 7 | D55: =COUNTIFS('API Test Cases'!C:C,"GRAD-103 · DELETE /beneficiaries/{id}",'API Test Cases'!M:M,"Automation") -> 6 | E55: =COUNTIFS('API Test Cases'!C:C,"GRAD-103 · DELETE /beneficiaries/{id}",'API Test Cases'!M:M,"Manual") -> 1 | F55: =COUNTIFS('API Test Cases'!C:C,"GRAD-103 · DELETE /beneficiaries/{id}",'API Test Cases'!K:K,"PASS ✓") -> 7 | G55: =COUNTIFS('API Test Cases'!C:C,"GRAD-103 · DELETE /beneficiaries/{id}",'API Test Cases'!K:K,"FAIL ✗") -> 0 | H55: =COUNTIFS('API Test Cases'!C:C,"GRAD-103 · DELETE /beneficiaries/{id}",'API Test Cases'!K:K,"Blocked") -> 0 | I55: =IFERROR(F55/(F55+G55),0) -> 1 | J55: =COUNTIFS('API Test Cases'!C:C,"GRAD-103 · DELETE /beneficiaries/{id}",'API Test Cases'!D:D,"Highest")+COUNTIFS('API Test Cases'!C:C,"GRAD-103 · DELETE /beneficiaries/{id}",'API Test Cases'!D:D,"High") -> 2 | M55: GRAD-103
B56: GRAD-201 · POST /cards | C56: =COUNTIF('API Test Cases'!C:C,"GRAD-201 · POST /cards") -> 21 | D56: =COUNTIFS('API Test Cases'!C:C,"GRAD-201 · POST /cards",'API Test Cases'!M:M,"Automation") -> 21 | E56: =COUNTIFS('API Test Cases'!C:C,"GRAD-201 · POST /cards",'API Test Cases'!M:M,"Manual") -> 0 | F56: =COUNTIFS('API Test Cases'!C:C,"GRAD-201 · POST /cards",'API Test Cases'!K:K,"PASS ✓") -> 21 | G56: =COUNTIFS('API Test Cases'!C:C,"GRAD-201 · POST /cards",'API Test Cases'!K:K,"FAIL ✗") -> 0 | H56: =COUNTIFS('API Test Cases'!C:C,"GRAD-201 · POST /cards",'API Test Cases'!K:K,"Blocked") -> 0 | I56: =IFERROR(F56/(F56+G56),0) -> 1 | J56: =COUNTIFS('API Test Cases'!C:C,"GRAD-201 · POST /cards",'API Test Cases'!D:D,"Highest")+COUNTIFS('API Test Cases'!C:C,"GRAD-201 · POST /cards",'API Test Cases'!D:D,"High") -> 12 | M56: GRAD-201
B57: GRAD-202 · GET /cards/{id} | C57: =COUNTIF('API Test Cases'!C:C,"GRAD-202 · GET /cards/{id}") -> 6 | D57: =COUNTIFS('API Test Cases'!C:C,"GRAD-202 · GET /cards/{id}",'API Test Cases'!M:M,"Automation") -> 5 | E57: =COUNTIFS('API Test Cases'!C:C,"GRAD-202 · GET /cards/{id}",'API Test Cases'!M:M,"Manual") -> 1 | F57: =COUNTIFS('API Test Cases'!C:C,"GRAD-202 · GET /cards/{id}",'API Test Cases'!K:K,"PASS ✓") -> 6 | G57: =COUNTIFS('API Test Cases'!C:C,"GRAD-202 · GET /cards/{id}",'API Test Cases'!K:K,"FAIL ✗") -> 0 | H57: =COUNTIFS('API Test Cases'!C:C,"GRAD-202 · GET /cards/{id}",'API Test Cases'!K:K,"Blocked") -> 0 | I57: =IFERROR(F57/(F57+G57),0) -> 1 | J57: =COUNTIFS('API Test Cases'!C:C,"GRAD-202 · GET /cards/{id}",'API Test Cases'!D:D,"Highest")+COUNTIFS('API Test Cases'!C:C,"GRAD-202 · GET /cards/{id}",'API Test Cases'!D:D,"High") -> 3 | M57: GRAD-202
B58: GRAD-203 · POST /cards/{id}/block | C58: =COUNTIF('API Test Cases'!C:C,"GRAD-203 · POST /cards/{id}/block") -> 19 | D58: =COUNTIFS('API Test Cases'!C:C,"GRAD-203 · POST /cards/{id}/block",'API Test Cases'!M:M,"Automation") -> 17 | E58: =COUNTIFS('API Test Cases'!C:C,"GRAD-203 · POST /cards/{id}/block",'API Test Cases'!M:M,"Manual") -> 2 | F58: =COUNTIFS('API Test Cases'!C:C,"GRAD-203 · POST /cards/{id}/block",'API Test Cases'!K:K,"PASS ✓") -> 19 | G58: =COUNTIFS('API Test Cases'!C:C,"GRAD-203 · POST /cards/{id}/block",'API Test Cases'!K:K,"FAIL ✗") -> 0 | H58: =COUNTIFS('API Test Cases'!C:C,"GRAD-203 · POST /cards/{id}/block",'API Test Cases'!K:K,"Blocked") -> 0 | I58: =IFERROR(F58/(F58+G58),0) -> 1 | J58: =COUNTIFS('API Test Cases'!C:C,"GRAD-203 · POST /cards/{id}/block",'API Test Cases'!D:D,"Highest")+COUNTIFS('API Test Cases'!C:C,"GRAD-203 · POST /cards/{id}/block",'API Test Cases'!D:D,"High") -> 10 | M58: GRAD-203
B59: GRAD-204 · POST /cards/{id}/unblock | C59: =COUNTIF('API Test Cases'!C:C,"GRAD-204 · POST /cards/{id}/unblock") -> 9 | D59: =COUNTIFS('API Test Cases'!C:C,"GRAD-204 · POST /cards/{id}/unblock",'API Test Cases'!M:M,"Automation") -> 8 | E59: =COUNTIFS('API Test Cases'!C:C,"GRAD-204 · POST /cards/{id}/unblock",'API Test Cases'!M:M,"Manual") -> 1 | F59: =COUNTIFS('API Test Cases'!C:C,"GRAD-204 · POST /cards/{id}/unblock",'API Test Cases'!K:K,"PASS ✓") -> 9 | G59: =COUNTIFS('API Test Cases'!C:C,"GRAD-204 · POST /cards/{id}/unblock",'API Test Cases'!K:K,"FAIL ✗") -> 0 | H59: =COUNTIFS('API Test Cases'!C:C,"GRAD-204 · POST /cards/{id}/unblock",'API Test Cases'!K:K,"Blocked") -> 0 | I59: =IFERROR(F59/(F59+G59),0) -> 1 | J59: =COUNTIFS('API Test Cases'!C:C,"GRAD-204 · POST /cards/{id}/unblock",'API Test Cases'!D:D,"Highest")+COUNTIFS('API Test Cases'!C:C,"GRAD-204 · POST /cards/{id}/unblock",'API Test Cases'!D:D,"High") -> 4 | M59: GRAD-204
B60: GRAD-301 · GET /billers | C60: =COUNTIF('API Test Cases'!C:C,"GRAD-301 · GET /billers") -> 6 | D60: =COUNTIFS('API Test Cases'!C:C,"GRAD-301 · GET /billers",'API Test Cases'!M:M,"Automation") -> 5 | E60: =COUNTIFS('API Test Cases'!C:C,"GRAD-301 · GET /billers",'API Test Cases'!M:M,"Manual") -> 1 | F60: =COUNTIFS('API Test Cases'!C:C,"GRAD-301 · GET /billers",'API Test Cases'!K:K,"PASS ✓") -> 6 | G60: =COUNTIFS('API Test Cases'!C:C,"GRAD-301 · GET /billers",'API Test Cases'!K:K,"FAIL ✗") -> 0 | H60: =COUNTIFS('API Test Cases'!C:C,"GRAD-301 · GET /billers",'API Test Cases'!K:K,"Blocked") -> 0 | I60: =IFERROR(F60/(F60+G60),0) -> 1 | J60: =COUNTIFS('API Test Cases'!C:C,"GRAD-301 · GET /billers",'API Test Cases'!D:D,"Highest")+COUNTIFS('API Test Cases'!C:C,"GRAD-301 · GET /billers",'API Test Cases'!D:D,"High") -> 0 | M60: GRAD-301
B61: GRAD-302 · POST /bill-payments | C61: =COUNTIF('API Test Cases'!C:C,"GRAD-302 · POST /bill-payments") -> 35 | D61: =COUNTIFS('API Test Cases'!C:C,"GRAD-302 · POST /bill-payments",'API Test Cases'!M:M,"Automation") -> 32 | E61: =COUNTIFS('API Test Cases'!C:C,"GRAD-302 · POST /bill-payments",'API Test Cases'!M:M,"Manual") -> 3 | F61: =COUNTIFS('API Test Cases'!C:C,"GRAD-302 · POST /bill-payments",'API Test Cases'!K:K,"PASS ✓") -> 35 | G61: =COUNTIFS('API Test Cases'!C:C,"GRAD-302 · POST /bill-payments",'API Test Cases'!K:K,"FAIL ✗") -> 0 | H61: =COUNTIFS('API Test Cases'!C:C,"GRAD-302 · POST /bill-payments",'API Test Cases'!K:K,"Blocked") -> 0 | I61: =IFERROR(F61/(F61+G61),0) -> 1 | J61: =COUNTIFS('API Test Cases'!C:C,"GRAD-302 · POST /bill-payments",'API Test Cases'!D:D,"Highest")+COUNTIFS('API Test Cases'!C:C,"GRAD-302 · POST /bill-payments",'API Test Cases'!D:D,"High") -> 22 | M61: GRAD-302
B62: GRAD-303 · GET /bill-payments | C62: =COUNTIF('API Test Cases'!C:C,"GRAD-303 · GET /bill-payments") -> 15 | D62: =COUNTIFS('API Test Cases'!C:C,"GRAD-303 · GET /bill-payments",'API Test Cases'!M:M,"Automation") -> 13 | E62: =COUNTIFS('API Test Cases'!C:C,"GRAD-303 · GET /bill-payments",'API Test Cases'!M:M,"Manual") -> 2 | F62: =COUNTIFS('API Test Cases'!C:C,"GRAD-303 · GET /bill-payments",'API Test Cases'!K:K,"PASS ✓") -> 15 | G62: =COUNTIFS('API Test Cases'!C:C,"GRAD-303 · GET /bill-payments",'API Test Cases'!K:K,"FAIL ✗") -> 0 | H62: =COUNTIFS('API Test Cases'!C:C,"GRAD-303 · GET /bill-payments",'API Test Cases'!K:K,"Blocked") -> 0 | I62: =IFERROR(F62/(F62+G62),0) -> 1 | J62: =COUNTIFS('API Test Cases'!C:C,"GRAD-303 · GET /bill-payments",'API Test Cases'!D:D,"Highest")+COUNTIFS('API Test Cases'!C:C,"GRAD-303 · GET /bill-payments",'API Test Cases'!D:D,"High") -> 1 | M62: GRAD-303
...

Sheet Web Test Cases
A1: TC ID | B1: TC Title | C1: Module/Feature | D1: Priority | E1: Test Type | F1: Preconditions | G1: Test Steps | H1: Test Data | I1: Expected Result | J1: Actual Result | K1: Status | L1: Notes | M1: Execution Type | N1: Regression | O1: Manual / Automation əsaslandırması
A2: TC-SRCH-001 | B2: Marka filtri ilə axtarışın yoxlanılması | C2: Əsas axtarış | D2: High | E2: Functional | F2: Brauzerdə https://turbo.az ana səhifəsi açıqdır | G2: 1. Marka siyahısından Toyota seç 2. "Elanları göstər" düyməsinə kliklə 3. Nəticə siyahısındakı elan başlıqlarına bax | H2: Marka: Toyota | I2: Siyahıdakı ("ELANLAR" bölməsi) bütün elanların başlığı "Toyota" ilə başlayır; ən azı 1 elan göstərilir | J2: Siyahıdakı bütün elanlar Toyota-dır ("Toyota almaq", ~2800 elan). Avtomat icra (Gauge + Selenium, 02.10.2026) | K2: PASS ✓ | L2: TS-01 | M2: Automation | N2: Yes | O2: Saytın əsas biznes axınıdır, hər relizdə yoxlanmalıdır. Konkret elana yox, qaydaya (bütün başlıqlar Toyota) assert olunur, buna görə data dəyişsə də stabildir
A3: TC-SRCH-002 | B3: Marka və model filtri ilə axtarışın yoxlanılması | C3: Əsas axtarış | D3: High | E3: Functional | F3: Brauzerdə https://turbo.az ana səhifəsi açıqdır | G3: 1. Marka: Toyota seç 2. Model: Camry seç 3. "Elanları göstər" düyməsinə kliklə | H3: Marka: Toyota / Model: Camry | I3: Siyahıdakı bütün elanların başlığı "Toyota Camry" ilə başlayır | J3: Bütün elanlar Toyota Camry-dir. Avtomat icra (Gauge + Selenium, 02.10.2026) | K3: PASS ✓ | L3: TS-01 | M3: Automation | N3: Yes | O3: Ən çox istifadə olunan axtarış kombinasiyasıdır. Nəticə qayda ilə yoxlanılır, stabildir
A4: TC-SRCH-003 | B4: Marka dəyişdikdə model siyahısının yenilənməsi | C4: Əsas axtarış | D4: Medium | E4: Functional | F4: Brauzerdə https://turbo.az ana səhifəsi açıqdır | G4: 1. Marka: Toyota seç 2. Model siyahısını aç 3. Markanı BMW-yə dəyiş 4. Model siyahısını yenidən aç | H4: Marka: Toyota → BMW | I4: Toyota seçildikdə model siyahısında Toyota modelləri (Camry) var, BMW modelləri (X5) yoxdur; BMW seçildikdə BMW modelləri (X5) göstərilir, Toyota modelləri (Camry) göstərilmir | J4: Toyota seçildikdə Camry var, X5 yoxdur; BMW seçildikdə X5 var, Camry yoxdur. Avtomat icra (Gauge + Selenium, 02.10.2026) | K4: PASS ✓ | L4: TS-01 | M4: Automation | N4: Yes | O4: Asılı dropdown məntiqidir, frontend dəyişikliklərində asanlıqla qırılır. Model siyahısı sabit kataloqdan gəlir, elanlardan asılı deyil → stabil
A5: TC-SRCH-004 | B5: Şəhər filtri ilə axtarışın yoxlanılması | C5: Əsas axtarış | D5: High | E5: Functional | F5: Brauzerdə https://turbo.az ana səhifəsi açıqdır | G5: 1. Şəhər siyahısından Gəncə seç 2. "Elanları göstər" düyməsinə kliklə 3. Elan kartlarında şəhər adına bax | H5: Şəhər: Gəncə | I5: Siyahıdakı bütün elan kartlarında şəhər "Gəncə" göstərilir | J5: Bütün elan kartlarında şəhər "Gəncə"-dir. Avtomat icra (Gauge + Selenium, 02.10.2026) | K5: PASS ✓ | L5: TS-01 | M5: Automation | N5: Yes | O5: Əsas filtrdir. Hər kartda şəhər adı göstərildiyi üçün assert sadə və etibarlıdır
A6: TC-SRCH-005 | B6: "Yeni" avtomobil filtrinin yoxlanılması | C6: Əsas axtarış | D6: Medium | E6: Functional | F6: Brauzerdə https://turbo.az ana səhifəsi açıqdır | G6: 1. "Yeni" seçimini et 2. "Elanları göstər" düyməsinə kliklə 3. Siyahıdakı ilk 3 elanı ayrı-ayrılıqda aç 4. Xüsusiyyətlər blokunda "Yeni" sahəsinə bax | H6: Vəziyyət: Yeni | I6: Açılan hər elanda "Yeni: Bəli" göstərilir | J6: İlk 3 elanın hər birində "Yeni: Bəli" göstərilir. Avtomat icra (Gauge + Selenium, 02.10.2026) | K6: PASS ✓ | L6: TS-01 | M6: Automation | N6: Yes | O6: Alıcının əsas seçimlərindən biridir. İlk 3 elanla məhdudlaşdırılır ki, test sürətli qalsın
A7: TC-SRCH-006 | B7: "Sürülmüş" avtomobil filtrinin yoxlanılması | C7: Əsas axtarış | D7: Medium | E7: Functional | F7: Brauzerdə https://turbo.az ana səhifəsi açıqdır | G7: 1. "Sürülmüş" seçimini et 2. "Elanları göstər" düyməsinə kliklə 3. İlk 3 elanı aç və "Yeni" sahəsinə bax | H7: Vəziyyət: Sürülmüş | I7: Açılan hər elanda "Yeni: Xeyr" göstərilir | J7: Gözlənilən nəticə təsdiqləndi: Açılan hər elanda "Yeni: Xeyr" göstərilir. Manual icra (02.10.2026) | K7: PASS ✓ | L7: TS-01 | M7: Manual | N7: No | O7: TC-SRCH-005 ilə eyni məntiqi yoxlayır (güzgü halı). Avtomatlaşdırmaq regression-a əlavə dəyər vermir, test müddətini artırır
A8: TC-SRCH-007 | B8: Marka, model və şəhər kombinasiyası ilə axtarış | C8: Əsas axtarış | D8: High | E8: Functional | F8: Brauzerdə https://turbo.az ana səhifəsi açıqdır | G8: 1. Marka: Hyundai seç 2. Model: Santa Fe seç 3. Şəhər: Bakı seç 4. "Elanları göstər" düyməsinə kliklə | H8: Marka: Hyundai / Model: Santa Fe / Şəhər: Bakı | I8: Bütün elanların başlığı "Hyundai Santa Fe", şəhəri "Bakı"-dır | J8: Bütün elanlar Hyundai Santa Fe və Bakı-dır. Avtomat icra (Gauge + Selenium, 02.10.2026) | K8: PASS ✓ | L8: TS-01 | M8: Automation | N8: Yes | O8: Bir neçə filtrin birlikdə işləməsini yoxlayır (filtrlər bir-birini sıfırlamamalıdır). Real istifadəçi ssenarisidir
A9: TC-SRCH-008 | B9: Nəticəsi olmayan filtr kombinasiyasının yoxlanılması | C9: Əsas axtarış | D9: Medium | E9: Negative | F9: Brauzerdə https://turbo.az ana səhifəsi açıqdır | G9: 1. Marka: Aston Martin seç 2. Şəhər: Lerik seç 3. "Elanları göstər" düyməsinə kliklə | H9: Marka: Aston Martin / Şəhər: Lerik | I9: Heç bir Aston Martin elanı göstərilmir, "elan tapılmadı" tipli məlumat mesajı çıxır; səhifə xəta vermir | J9: Aston Martin + Lerik üçün elan yoxdur, "tapılmadı" mesajı göstərilir, səhifə xəta vermir. Avtomat icra (Gauge + Selenium, 02.10.2026) | K9: PASS ✓ | L9: TS-01 | M9: Automation | N9: Yes | O9: Boş nəticə halı tez-tez unudulan və regression-da qırılan haldır. Seçilmiş kombinasiyada elanın yaranma ehtimalı praktik olaraq sıfırdır
A10: TC-SRCH-009 | B10: Filtrlərin URL-də saxlanması və səhifə yeniləndikdə qalması | C10: Əsas axtarış | D10: Medium | E10: Functional | F10: Brauzerdə https://turbo.az ana səhifəsi açıqdır | G10: 1. Marka: Toyota seç və axtar 2. URL-ə bax 3. Səhifəni yenilə (F5) 4. Filtr sahəsinə və nəticələrə bax | H10: Marka: Toyota | I10: URL-də marka parametri (q[make][]) var; yeniləmədən sonra Toyota seçili qalır, bütün elanlar yenə Toyota-dır | J10: URL-də marka parametri var; yeniləmədən sonra Toyota seçili qalır, bütün elanlar Toyota-dır. Avtomat icra (Gauge + Selenium, 02.10.2026) | K10: PASS ✓ | L10: TS-01 | M10: Automation | N10: Yes | O10: İstifadəçilər axtarış linkini paylaşır. Yoxlama URL və sahə dəyərləri üzərindədir, data dəyişməsindən asılı deyil
A11: TC-SRCH-010 | B11: "Sıfırla" düyməsi ilə filtrlərin təmizlənməsi | C11: Əsas axtarış | D11: Medium | E11: Functional | F11: Brauzerdə https://turbo.az ana səhifəsi açıqdır | G11: 1. Marka: Toyota, Şəhər: Bakı, Qiymət min: 10000 seç 2. "Sıfırla" düyməsinə kliklə 3. Filtr sahələrinə bax | H11: Marka: Toyota / Şəhər: Bakı / Qiymət min: 10000 | I11: Bütün filtr sahələri ilkin (boş) vəziyyətə qayıdır | J11: "Sıfırla"-dan sonra marka, şəhər və qiymət sahələri boşalır. Avtomat icra (Gauge + Selenium, 02.10.2026) | K11: PASS ✓ | L11: TS-01 | M11: Automation | N11: Yes | O11: Sadə, sürətli və tam stabil testdir; filtr formasının vəziyyət idarəsini qoruyur
A12: TC-SRCH-011 | B12: "Sifarişlə" bölməsinin filtrləri | C12: Əsas axtarış | D12: Medium | E12: Functional | F12: Brauzerdə https://turbo.az ana səhifəsi açıqdır | G12: 1. Yuxarı menyuda "Sifarişlə" linkinə kliklə 2. URL-ə və elanlara bax | H12: Menyu: Sifarişlə | I12: URL-də availability_status=order parametri var, yalnız sifarişlə gətirilən elanlar göstərilir | J12: Gözlənilən nəticə təsdiqləndi: URL-də availability_status=order parametri var, yalnız sifarişlə gətirilən elanlar göstərilir. Manual icra (02.10.2026) | K12: PASS ✓ | L12: TS-01 | M12: Manual | N12: No | O12: Elanın "sifarişlə" olması kartda həmişə göstərilmir; nəticəni detal səhifədə manual yoxlamaq lazımdır
... A129: TC-UI-006 | B129: Filtr formasında klaviatura ilə naviqasiya | C129: UI/UX | D129: Low | E129: UI/UX | F129: Brauzerdə https://turbo.az ana səhifəsi açıqdır | G129: 1. Tab düyməsi ilə filtr sahələri arasında keç 2. Enter ilə axtarışı başlat | H129: Klaviatura: Tab / Enter | I129: Fokus ardıcıl keçir və görünür; Enter axtarışı başladır | J129: Gözlənilən nəticə təsdiqləndi: Fokus ardıcıl keçir və görünür; Enter axtarışı başladır. Manual icra (02.10.2026) | K129: PASS ✓ | L129: TS-13 | M129: Manual | N129: No | O129: Vizual qiymətləndirmə tələb edir

Sheet Web Test Scenarios
A1: Scenario ID | B1: Modul | C1: Test Ssenarisi | D1: Prioritet | E1: Test case sayı | F1: Automation | G1: Manual | H1: Regression-a daxil
A2: TS-01 | B2: Əsas axtarış | C2: İstifadəçi marka, model, şəhər və vəziyyət filtrləri ilə avtomobil axtarır | D2: High | E2: =COUNTIF('Web Test Cases'!$L:$L,A2) -> 14 | F2: =COUNTIFS('Web Test Cases'!$L:$L,A2,'Web Test Cases'!$M:$M,"Automation") -> 9 | G2: =COUNTIFS('Web Test Cases'!$L:$L,A2,'Web Test Cases'!$M:$M,"Manual") -> 5 | H2: =COUNTIFS('Web Test Cases'!$L:$L,A2,'Web Test Cases'!$N:$N,"Yes") -> 9
A3: TS-02 | B3: Qiymət filtri | C3: İstifadəçi qiymət aralığı və valyuta ilə elanları filtrləyir | D3: High | E3: =COUNTIF('Web Test Cases'!$L:$L,A3) -> 13 | F3: =COUNTIFS('Web Test Cases'!$L:$L,A3,'Web Test Cases'!$M:$M,"Automation") -> 4 | G3: =COUNTIFS('Web Test Cases'!$L:$L,A3,'Web Test Cases'!$M:$M,"Manual") -> 9 | H3: =COUNTIFS('Web Test Cases'!$L:$L,A3,'Web Test Cases'!$N:$N,"Yes") -> 4
A4: TS-03 | B4: Buraxılış ili filtri | C4: İstifadəçi buraxılış ili aralığı ilə elanları filtrləyir | D4: High | E4: =COUNTIF('Web Test Cases'!$L:$L,A4) -> 8 | F4: =COUNTIFS('Web Test Cases'!$L:$L,A4,'Web Test Cases'!$M:$M,"Automation") -> 1 | G4: =COUNTIFS('Web Test Cases'!$L:$L,A4,'Web Test Cases'!$M:$M,"Manual") -> 7 | H4: =COUNTIFS('Web Test Cases'!$L:$L,A4,'Web Test Cases'!$N:$N,"Yes") -> 1
A5: TS-04 | B5: Əlavə filtrlər | C5: İstifadəçi "Daha çox filtr" bölməsindəki parametrlərlə axtarışı dəqiqləşdirir | D5: Medium | E5: =COUNTIF('Web Test Cases'!$L:$L,A5) -> 25 | F5: =COUNTIFS('Web Test Cases'!$L:$L,A5,'Web Test Cases'!$M:$M,"Automation") -> 4 | G5: =COUNTIFS('Web Test Cases'!$L:$L,A5,'Web Test Cases'!$M:$M,"Manual") -> 21 | H5: =COUNTIFS('Web Test Cases'!$L:$L,A5,'Web Test Cases'!$N:$N,"Yes") -> 4
A6: TS-05 | B6: Sıralama | C6: İstifadəçi nəticələri qiymətə, yürüşə, ilə və tarixə görə sıralayır | D6: High | E6: =COUNTIF('Web Test Cases'!$L:$L,A6) -> 7 | F6: =COUNTIFS('Web Test Cases'!$L:$L,A6,'Web Test Cases'!$M:$M,"Automation") -> 3 | G6: =COUNTIFS('Web Test Cases'!$L:$L,A6,'Web Test Cases'!$M:$M,"Manual") -> 4 | H6: =COUNTIFS('Web Test Cases'!$L:$L,A6,'Web Test Cases'!$N:$N,"Yes") -> 3
A7: TS-06 | B7: Səhifələmə | C7: İstifadəçi nəticə səhifələri arasında keçid edir | D7: Medium | E7: =COUNTIF('Web Test Cases'!$L:$L,A7) -> 7 | F7: =COUNTIFS('Web Test Cases'!$L:$L,A7,'Web Test Cases'!$M:$M,"Automation") -> 1 | G7: =COUNTIFS('Web Test Cases'!$L:$L,A7,'Web Test Cases'!$M:$M,"Manual") -> 6 | H7: =COUNTIFS('Web Test Cases'!$L:$L,A7,'Web Test Cases'!$N:$N,"Yes") -> 1
A8: TS-07 | B8: Elan səhifəsi | C8: İstifadəçi elanın detal səhifəsinə baxır və satıcı ilə əlaqə məlumatını alır | D8: High | E8: =COUNTIF('Web Test Cases'!$L:$L,A8) -> 10 | F8: =COUNTIFS('Web Test Cases'!$L:$L,A8,'Web Test Cases'!$M:$M,"Automation") -> 3 | G8: =COUNTIFS('Web Test Cases'!$L:$L,A8,'Web Test Cases'!$M:$M,"Manual") -> 7 | H8: =COUNTIFS('Web Test Cases'!$L:$L,A8,'Web Test Cases'!$N:$N,"Yes") -> 4
A9: TS-08 | B9: Seçilmişlər | C9: İstifadəçi bəyəndiyi elanları seçilmişlərə əlavə edir və silir | D9: Medium | E9: =COUNTIF('Web Test Cases'!$L:$L,A9) -> 4 | F9: =COUNTIFS('Web Test Cases'!$L:$L,A9,'Web Test Cases'!$M:$M,"Automation") -> 2 | G9: =COUNTIFS('Web Test Cases'!$L:$L,A9,'Web Test Cases'!$M:$M,"Manual") -> 2 | H9: =COUNTIFS('Web Test Cases'!$L:$L,A9,'Web Test Cases'!$N:$N,"Yes") -> 2
A10: TS-09 | B10: Dil və naviqasiya | C10: İstifadəçi dili dəyişir və saytın əsas bölmələri arasında keçir | D10: Medium | E10: =COUNTIF('Web Test Cases'!$L:$L,A10) -> 9 | F10: =COUNTIFS('Web Test Cases'!$L:$L,A10,'Web Test Cases'!$M:$M,"Automation") -> 2 | G10: =COUNTIFS('Web Test Cases'!$L:$L,A10,'Web Test Cases'!$M:$M,"Manual") -> 7 | H10: =COUNTIFS('Web Test Cases'!$L:$L,A10,'Web Test Cases'!$N:$N,"Yes") -> 2
A11: TS-10 | B11: Giriş (Autentifikasiya) | C11: İstifadəçi telefon nömrəsi və SMS kodu ilə hesaba daxil olur | D11: High | E11: =COUNTIF('Web Test Cases'!$L:$L,A11) -> 12 | F11: =COUNTIFS('Web Test Cases'!$L:$L,A11,'Web Test Cases'!$M:$M,"Automation") -> 0 | G11: =COUNTIFS('Web Test Cases'!$L:$L,A11,'Web Test Cases'!$M:$M,"Manual") -> 12 | H11: =COUNTIFS('Web Test Cases'!$L:$L,A11,'Web Test Cases'!$N:$N,"Yes") -> 3
A12: TS-11 | B12: Yeni elan | C12: İstifadəçi yeni elan yerləşdirmə formasını açır və doldurur | D12: High | E12: =COUNTIF('Web Test Cases'!$L:$L,A12) -> 12 | F12: =COUNTIFS('Web Test Cases'!$L:$L,A12,'Web Test Cases'!$M:$M,"Automation") -> 0 | G12: =COUNTIFS('Web Test Cases'!$L:$L,A12,'Web Test Cases'!$M:$M,"Manual") -> 12 | H12: =COUNTIFS('Web Test Cases'!$L:$L,A12,'Web Test Cases'!$N:$N,"Yes") -> 2
A13: TS-12 | B13: Ödənişli xidmətlər | C13: İstifadəçi elan üçün ödənişli xidmət (İrəli çək, VIP, Premium) seçimlərinə baxır | D13: Low | E13: =COUNTIF('Web Test Cases'!$L:$L,A13) -> 1 | F13: =COUNTIFS('Web Test Cases'!$L:$L,A13,'Web Test Cases'!$M:$M,"Automation") -> 0 | G13: =COUNTIFS('Web Test Cases'!$L:$L,A13,'Web Test Cases'!$M:$M,"Manual") -> 1 | H13: =COUNTIFS('Web Test Cases'!$L:$L,A13,'Web Test Cases'!$N:$N,"Yes") -> 0
A14: TS-13 | B14: UI/UX | C14: Saytın müxtəlif ekran və brauzerlərdə düzgün görünməsi | D14: Medium | E14: =COUNTIF('Web Test Cases'!$L:$L,A14) -> 6 | F14: =COUNTIFS('Web Test Cases'!$L:$L,A14,'Web Test Cases'!$M:$M,"Automation") -> 0 | G14: =COUNTIFS('Web Test Cases'!$L:$L,A14,'Web Test Cases'!$M:$M,"Manual") -> 6 | H14: =COUNTIFS('Web Test Cases'!$L:$L,A14,'Web Test Cases'!$N:$N,"Yes") -> 0
A15: CƏMİ | E15: =SUM(E2:E14) -> 128 | F15: =SUM(F2:F14) -> 29 | G15: =SUM(G2:G14) -> 99 | H15: =SUM(H2:H14) -> 35
A17: Qeydlər:
A18: Execution Type = Automation olan bütün test case-lər regression paketinə daxildir və avtomatlaşdırılacaq.
A19: Execution Type = Manual + Regression = Yes: kritik axındır, lakin texniki səbəbdən (SMS, real elan, şəxsi məlumat) avtomatlaşdırıla bilmir, hər relizdə manual icra olunur.
A20: Actual Result və Status sütunları icradan sonra doldurulur (başlanğıc status: Not Run).
A21: Sıralama testlərində VIP / Premium blokları nəzərə alınmır, yalnız "ELANLAR" siyahısı yoxlanılır.

Sheet Web Test Scope
A1: Layihə: turbo.az (https://turbo.az/autos) — Test Scope
A2: Yanaşma: risk əsaslı test. 2 həftəlik müddətdə saytın əsas biznes axını ("avtomobil tap → elanı aç → satıcı ilə əlaqə") dərindən, digər funksiyalar məhdud şəkildə test olunur.
A4: 1. Scope-a daxil olanlar (In Scope)
A5: Modul | B5: Nə yoxlanılır | C5: Test yanaşması | D5: Qeyd
A6: Əsas axtarış | B6: Marka, model, şəhər, vəziyyət filtrləri, kombinasiyalar, URL, sıfırlama | C6: Manual + Automation | D6: Əsas biznes axını, regression-ın nüvəsi
A7: Qiymət və il filtrləri | B7: Aralıqlar, sərhəd dəyərləri, negativ daxiletmələr, valyuta | C7: Manual + Automation | D7: Sərhəd və validasiya xətaları ən çox burada çıxır
A8: Əlavə filtrlər | B8: Yanacaq, ban, sürətlər qutusu, yürüş, mühərrik, güc, kredit/barter və s. | C8: Manual + Automation | D8: Kartda görünən filtrlər avtomat, detal tələb edənlər manual
A9: Sıralama | B9: Qiymət (artan/azalan), yürüş, il, tarix; filtrlə birlikdə | C9: Manual + Automation | D9: VIP/Premium bloklar sıralamaya tabe deyil, yoxlamadan kənardır
A10: Səhifələmə | B10: Səhifələr arası keçid, filtrin qorunması | C10: Manual + Automation
A11: Elan səhifəsi | B11: Kart-detal uyğunluğu, xüsusiyyətlər bloku, qalereya, nömrə, 404 | C11: Manual + Automation | D11: "Nömrəni göstər" etik səbəbdən yalnız manual
A12: Seçilmişlər | B12: Əlavə, silmə, sessiyada qalma | C12: Manual + Automation
A13: Dil və naviqasiya | B13: AZ/RU keçidi, menyu və footer linkləri | C13: Manual + Automation
A14: Giriş (Autentifikasiya) | B14: Telefon + SMS ilə giriş, validasiya, sessiya, çıxış | C14: Yalnız Manual | D14: SMS kodu avtomatlaşdırıla bilmir
A15: Yeni elan | B15: Forma, validasiya, şəkil yükləmə | C15: Yalnız Manual | D15: Forma heç vaxt düzgün data ilə göndərilmir
A16: Ödənişli xidmətlər | B16: Paketlərin və qiymətlərin göstərilməsi | C16: Yalnız Manual | D16: Ödəniş addımı icra edilmir
A17: UI/UX | B17: Responsive (375/768px), zoom, klaviatura, cross-browser | C17: Yalnız Manual | D17: Vizual qiymətləndirmə
A19: 2. Scope-dan kənar qalanlar (Out of Scope) — nəyi test etmədik və niyə
A20: Sahə | B20: Niyə test edilmədi | C20: Risk | D20: Gələcək üçün tövsiyə
A21: Moto, Ehtiyat hissələri, Mağazalar bölmələri | B21: Əsas axına (avtomobil alışı) aid deyil; axtarış/filtr məntiqi /autos bölməsi ilə eynidir | C21: Aşağı | D21: Eyni test dizaynı ilə genişləndirilə bilər
A22: Avtokataloq (dərindən) | B22: Məlumat xarakterli bölmədir; yalnız açılması yoxlanılıb (TC-NAV-007) | C22: Aşağı | D22: Kataloq datasının düzgünlüyü ayrıca yoxlanıla bilər
A23: Biznes hesabı və diler paneli | B23: Real biznes (diler) hesabı tələb edir, test hesabı yoxdur | C23: Orta | D23: Operatordan test hesabı alındıqda əlavə edilməli
A24: Elan yerləşdirmənin tam axını (göndərmə, moderasiya) | B24: Canlı sistemdə real elan yaradır, moderatorlara və alıcılara təsir edir | C24: Yüksək | D24: Test (staging) mühitində icra edilməlidir
A25: Ödəniş əməliyyatları (VIP, Premium, İrəli çək) | B25: Real pul əməliyyatıdır | C25: Yüksək | D25: Staging mühitində test kartları ilə
A26: "Şikayət et" formasının göndərilməsi | B26: Real elana saxta şikayət göndərilmiş olar | C26: Aşağı | D26: Staging mühitində
A27: Mobil tətbiqlər (iOS/Android) | B27: Ayrı məhsuldur, ayrı alət (Appium) tələb edir | C27: Orta | D27: Ayrı layihə kimi
A28: Performans / yük testi | B28: Canlı saytda yük yaratmaq etik və hüquqi baxımdan qəbuledilməzdir | C28: Orta | D28: Staging mühitində JMeter/k6 ilə
A29: Təhlükəsizlik testi (penetration) | B29: Sahibinin icazəsi olmadan qanunsuzdur | C29: Yüksək | D29: Rəsmi icazə ilə mütəxəssis tərəfindən
A30: Elan datasının düzgünlüyü (satıcının yazdığı məlumat) | B30: Elan sahibinin məsuliyyətidir, sistem funksionallığı deyil | C30: Aşağı | D30: —
A31: Email/push bildirişləri, mesajlaşma | B31: Real hesab və qarşı tərəf tələb edir | C31: Aşağı | D31: Staging mühitində
A33: 3. Fərziyyələr və məhdudiyyətlər
A34: • Testlər canlı (production) mühitdə aparılır; test datası dinamikdir, ona görə avtomat testlər konkret elana yox, qaydaya assert edir.
A35: • Test mühiti: Windows/macOS, Google Chrome (son versiya); cross-browser yoxlaması manual aparılır.
A36: • Avtomatlaşdırma müəllimin təqdim etdiyi arxitektura üzərində, dəyişiklik edilmədən yazılır.
A37: • Canlı sayta yük yaratmamaq üçün avtomat paket məhdud sayda işə salınır.

Sheet Tapıntılar
A1: ID | B1: Başlıq | C1: Modul | D1: Severity | E1: Priority | F1: Əlaqəli TC | G1: Mühit | H1: Ön şərt | I1: Addımlar | J1: Test data | K1: Gözlənilən nəticə | L1: Faktiki nəticə | M1: Təsir / qeyd | N1: Əlavələr | O1: Status | P1: Növ
A2: UYG-001 | B2: Əlavə filtrlər: "Vuruğu yoxdur" və "Yalnız qəzalı avtomobillər" eyni anda seçilə bilir; nəticədə vuruğu olan avtomobillər göstərilir (filtrlər bir-birinə uyğun işləmir) | C2: Əlavə filtrlər ("Daha çox filtr" → Vəziyyəti) | D2: Minor | E2: Low | F2: TC-FLTR-024 | G2: Production — https://turbo.az, Google Chrome (Windows 11), qonaq istifadəçi | H2: turbo.az ana səhifəsi açıqdır, "Daha çox filtr" bölməsi açılıb | I2: 1. "Vuruğu yoxdur" seçimini işarələ 2. "Yalnız qəzalı avtomobillər" seçimini işarələ 3. "Elanları göstər" düyməsinə kliklə 4. Nəticədəki elanları aç və "Vəziyyəti" sahəsinə bax | J2: Vuruğu yoxdur: ✓ / Yalnız qəzalı avtomobillər: ✓ | K2: Sistem ziddiyyətli seçimi idarə edir: bir seçim işarələnəndə digəri deaktiv olur (və ya avtomatik götürülür), ya da "elan tapılmadı" göstərilir | L2: Hər iki seçim eyni anda işarələnə bilir, xəbərdarlıq yoxdur. Nəticədə vuruğu olan, əzilmiş avtomobillər göstərilir — "Vuruğu yoxdur" filtri nəzərə alınmır | M2: turbo.az üçün yazılı tələb olmadığına görə bug kimi yox, uyğunsuzluq kimi qeyd edilib: iki ziddiyyətli filtr eyni anda seçilə bilir və "Vuruğu yoxdur" şərti nəzərə alınmır. İstifadəçi "Vuruğu yoxdur" seçdiyini görüb nəticələrə güvənə bilər. Məhsul komandası ilə dəqiqləşdirilməlidir | N2: — | O2: New | P2: Uyğunsuzluq
A3: UYG-002 | B3: Yeni elan: təsvir sahəsinə 3000 simvoldan uzun mətn yapışdırıldıqda artıq hissə xəbərdarlıq edilmədən silinir | C3: Yeni elan forması — Təsvir sahəsi | D3: Major | E3: Medium | F3: TC-NEWAD-012 | G3: Production — https://turbo.az, Google Chrome (Windows 11) | H3: "Yeni elan" forması açıqdır | I3: 1. 5000 simvolluq mətni kopyala 2. Təsvir sahəsinə yapışdır (Ctrl+V) 3. Sahədəki mətnin uzunluğuna və sonuna bax | J3: Təsvir: 5000 simvol (copy-paste) | K3: İstifadəçi limit barədə xəbərdar edilir: simvol sayğacı göstərilir və ya "maksimum 3000 simvol" mesajı çıxır | L3: Sahə yalnız ilk 3000 simvolu qəbul edir, qalan 2000 simvol heç bir xəbərdarlıq, sayğac və ya mesaj olmadan silinir | M3: Görünməz data itkisi: istifadəçi mətnin sonunun kəsildiyini görməyə bilər və elan yarımçıq təsvirlə dərc olunar. Yazılı tələb olmadığına görə uyğunsuzluq kimi qeyd edilib | N3: — | O3: New | P3: Uyğunsuzluq
A4: UYG-003 | B4: Qiymət filtri: onluq ayırıcı (nöqtə/vergül) qəbul edilmir, amma istifadəçiyə bu barədə məlumat verilmir | C4: Qiymət filtri (ana səhifə axtarış forması) | D4: Minor | E4: Low | F4: TC-PRICE-012 | G4: Production — https://turbo.az, Google Chrome (Windows 11) | H4: turbo.az ana səhifəsi açıqdır | I4: 1. "Qiymət, min." sahəsinə 10000.50 daxil et 2. Nöqtəni yazarkən sahənin ətrafına və altına bax 3. Eyni yoxlamanı vergüllə təkrarla: 10000,50 4. "Elanları göstər" düyməsinə kliklə | J4: Qiymət, min: 10000.50 və 10000,50 | K4: İstifadəçi nöqtə (.) və ya vergül (,) daxil etməyə çalışdıqda simvol qəbul edilmir və sahənin altında qırmızı rəngli inline validasiya mesajı göstərilir, məsələn: "Qiymət yalnız tam ədəd ola bilər. Nöqtə və vergül istifadə etməyin." Mesaj istifadəçi düzgün dəyər daxil etdikdə avtomatik itir | L4: Nöqtə qəbul edilmir, qalan rəqəmlər birləşir: sahədə "1 000 050" görünür. Heç bir ipucu və ya mesaj yoxdur; axtarış 0 elan qaytarır | M4: Dəyər sahədə görünür, ona görə test keçib (TC-PRICE-012 PASS). Amma istifadəçi nöqtənin niyə yazılmadığını, dəyərin niyə 100 dəfə böyüdüyünü və nəticənin niyə boş olduğunu anlamaya bilər. Təkmilləşdirmə təklifi: yanlış simvol daxil edildikdə inline validasiya mesajı göstərmək | N4: — | O4: New | P4: Uyğunsuzluq

Sheet API Test Cases
A1: TC ID | B1: TC Title | C1: Module/Feature | D1: Priority | E1: Test Type | F1: Preconditions | G1: Test Steps | H1: Test Data | I1: Expected Result | J1: Actual Result | K1: Status | L1: AC Reference | M1: Execution Type | N1: Regression | O1: Manual / Automation əsaslandırması
A2: TC-API-101-001 | B2: Etibarlı sorğu ilə alıcı yaradılması | C2: GRAD-101 · POST /beneficiaries | D2: High | E2: Functional | F2: user1 ilə POST /auth/login edilib, token alınıb (base spec-də Authorization header) | G2: 1. POST /beneficiaries göndər 2. Status, Location header və body-ni yoxla | H2: {"fullName":"Nigar Əliyeva","iban":"AZ77AIIB40060019440123456789","currency":"AZN","nickname":"Anam"} | I2: 201 Created; Location = /beneficiaries/{id}; id ^ben_[a-z0-9]{8}$; iban, ibanMasked, currency, nickname, createdAt (ISO-8601) mövcuddur və göndərilən data ilə uyğundur; JSON schema-ya uyğundur | J2: Gözlənilən nəticə alındı: 201 Created; Location = /beneficiaries/{id}; id ^ben_[a-z0-9]{8}$; iban, ibanMasked, currency, nickname, createdAt (ISO-8601) mövcuddur və göndərilən data ilə uyğundur; JSON schema-ya uyğundur. Avtomat icra (Gauge + RestAssured, 02.10.2026), 3 icrada stabil | K2: PASS ✓ | L2: GRAD-101 AC-1 | M2: Automation | N2: Yes | O2: Deterministik API testi: sandbox hər login-də təmiz mühit verir. Status + body sahələri + code assert olunur; hər relizdə icra olunmalıdır
A3: TC-API-101-002 | B3: IBAN-ın normallaşdırılması (boşluq + kiçik hərf) | C3: GRAD-101 · POST /beneficiaries | D3: High | E3: Functional | F3: user1 ilə POST /auth/login edilib, token alınıb (base spec-də Authorization header) | G3: 1. IBAN-ı boşluqlu və kiçik hərflə POST /beneficiaries göndər 2. Cavabdakı iban-a bax | H3: iban: "az77 aiib 4006 0019 4401 2345 6789" | I3: 201; iban = "AZ77AIIB40060019440123456789" (boşluqsuz, böyük hərf); ibanMasked AZ77 ilə başlayır, son 4 rəqəm 6789 | J3: Gözlənilən nəticə alındı: 201; iban = "AZ77AIIB40060019440123456789" (boşluqsuz, böyük hərf); ibanMasked AZ77 ilə başlayır, son 4 rəqəm 6789. Avtomat icra (Gauge + RestAssured, 02.10.2026), 3 icrada stabil | K3: PASS ✓ | L3: GRAD-101 AC-2 | M3: Automation | N3: Yes | O3: Deterministik API testi: sandbox hər login-də təmiz mühit verir. Status + body sahələri + code assert olunur; hər relizdə icra olunmalıdır
A4: TC-API-101-003 | B4: nickname göndərilmədikdə null qaytarılması | C4: GRAD-101 · POST /beneficiaries | D4: Medium | E4: Functional | F4: user1 ilə POST /auth/login edilib, token alınıb (base spec-də Authorization header) | G4: 1. nickname sahəsi olmadan POST /beneficiaries göndər | H4: nickname: (göndərilmir) | I4: 201; body-də "nickname": null (sahə mövcuddur, dəyəri null) | J4: Gözlənilən nəticə alındı: 201; body-də "nickname": null (sahə mövcuddur, dəyəri null). Avtomat icra (Gauge + RestAssured, 02.10.2026), 3 icrada stabil | K4: PASS ✓ | L4: GRAD-101 AC-3 | M4: Automation | N4: Yes | O4: Deterministik API testi: sandbox hər login-də təmiz mühit verir. Status + body sahələri + code assert olunur; hər relizdə icra olunmalıdır
A5: TC-API-101-004 | B5: Bir neçə səhv sahə eyni anda göndərildikdə details-də hamısının göstərilməsi | C5: GRAD-101 · POST /beneficiaries | D5: High | E5: Negative | F5: user1 ilə POST /auth/login edilib, token alınıb (base spec-də Authorization header) | G5: 1. 3 sahəsi səhv olan POST /beneficiaries göndər 2. details massivini yoxla | H5: fullName: "A", iban: "XX00", currency: "GBP" | I5: 400; code = VALIDATION_ERROR; details-də field = fullName, iban, currency üçün ayrıca {field, message} obyekti var (3 element) | J5: Gözlənilən nəticə alındı: 400; code = VALIDATION_ERROR; details-də field = fullName, iban, currency üçün ayrıca {field, message} obyekti var (3 element). Avtomat icra (Gauge + RestAssured, 02.10.2026), 3 icrada stabil | K5: PASS ✓ | L5: GRAD-101 AC-4 | M5: Automation | N5: Yes | O5: Validasiya qaydası — code (mətn yox) və details[].field assert olunur; ucuz, sürətli və stabildir
A6: TC-API-101-005 | B6: fullName — 1 simvol (aşağı sərhəd − 1) | C6: GRAD-101 · POST /beneficiaries | D6: High | E6: Boundary Value | F6: user1 ilə POST /auth/login edilib, token alınıb (base spec-də Authorization header) | G6: 1. POST /beneficiaries göndər | H6: fullName: "A" | I6: 400 VALIDATION_ERROR; details[].field = "fullName" | J6: Gözlənilən nəticə alındı: 400 VALIDATION_ERROR; details[].field = "fullName". Avtomat icra (Gauge + RestAssured, 02.10.2026), 3 icrada stabil | K6: PASS ✓ | L6: GRAD-101 AC-5 | M6: Automation | N6: Yes | O6: Sərhəd dəyəri — TestNG DataProvider ilə data-driven avtomatlaşdırılır; sərhəd səhvləri (< / ≤) regression-da tez-tez qırılır
A7: TC-API-101-006 | B7: fullName — 2 simvol (aşağı sərhəd) | C7: GRAD-101 · POST /beneficiaries | D7: High | E7: Boundary Value | F7: user1 ilə POST /auth/login edilib, token alınıb (base spec-də Authorization header) | G7: 1. POST /beneficiaries göndər | H7: fullName: "Al" | I7: 201; fullName = "Al" | J7: Gözlənilən nəticə alındı: 201; fullName = "Al". Avtomat icra (Gauge + RestAssured, 02.10.2026), 3 icrada stabil | K7: PASS ✓ | L7: GRAD-101 AC-5 | M7: Automation | N7: Yes | O7: Sərhəd dəyəri — TestNG DataProvider ilə data-driven avtomatlaşdırılır; sərhəd səhvləri (< / ≤) regression-da tez-tez qırılır
A8: TC-API-101-007 | B8: fullName — 50 simvol (yuxarı sərhəd) | C8: GRAD-101 · POST /beneficiaries | D8: High | E8: Boundary Value | F8: user1 ilə POST /auth/login edilib, token alınıb (base spec-də Authorization header) | G8: 1. POST /beneficiaries göndər | H8: fullName: 50 hərf | I8: 201; fullName tam saxlanılıb (50 simvol) | J8: Gözlənilən nəticə alındı: 201; fullName tam saxlanılıb (50 simvol). Avtomat icra (Gauge + RestAssured, 02.10.2026), 3 icrada stabil | K8: PASS ✓ | L8: GRAD-101 AC-5 | M8: Automation | N8: Yes | O8: Sərhəd dəyəri — TestNG DataProvider ilə data-driven avtomatlaşdırılır; sərhəd səhvləri (< / ≤) regression-da tez-tez qırılır
A9: TC-API-101-008 | B9: fullName — 51 simvol (yuxarı sərhəd + 1) | C9: GRAD-101 · POST /beneficiaries | D9: High | E9: Boundary Value | F9: user1 ilə POST /auth/login edilib, token alınıb (base spec-də Authorization header) | G9: 1. POST /beneficiaries göndər | H9: fullName: 51 hərf | I9: 400 VALIDATION_ERROR; details[].field = "fullName" | J9: Gözlənilən nəticə alındı: 400 VALIDATION_ERROR; details[].field = "fullName". Avtomat icra (Gauge + RestAssured, 02.10.2026), 3 icrada stabil | K9: PASS ✓ | L9: GRAD-101 AC-5 | M9: Automation | N9: Yes | O9: Sərhəd dəyəri — TestNG DataProvider ilə data-driven avtomatlaşdırılır; sərhəd səhvləri (< / ≤) regression-da tez-tez qırılır
A10: TC-API-101-009 | B10: fullName hərflə başlamır ("---") | C10: GRAD-101 · POST /beneficiaries | D10: Medium | E10: Negative | F10: user1 ilə POST /auth/login edilib, token alınıb (base spec-də Authorization header) | G10: 1. POST /beneficiaries göndər | H10: fullName: "---" | I10: 400 VALIDATION_ERROR; details[].field = "fullName" | J10: Gözlənilən nəticə alındı: 400 VALIDATION_ERROR; details[].field = "fullName". Avtomat icra (Gauge + RestAssured, 02.10.2026), 3 icrada stabil | K10: PASS ✓ | L10: GRAD-101 AC-6 | M10: Automation | N10: Yes | O10: Validasiya qaydası — code (mətn yox) və details[].field assert olunur; ucuz, sürətli və stabildir
A11: TC-API-101-010 | B11: fullName-də rəqəm var ("Ali2") | C11: GRAD-101 · POST /beneficiaries | D11: Medium | E11: Negative | F11: user1 ilə POST /auth/login edilib, token alınıb (base spec-də Authorization header) | G11: 1. POST /beneficiaries göndər | H11: fullName: "Ali2" | I11: 400 VALIDATION_ERROR; details[].field = "fullName" | J11: Gözlənilən nəticə alındı: 400 VALIDATION_ERROR; details[].field = "fullName". Avtomat icra (Gauge + RestAssured, 02.10.2026), 3 icrada stabil | K11: PASS ✓ | L11: GRAD-101 AC-6 | M11: Automation | N11: Yes | O11: Validasiya qaydası — code (mətn yox) və details[].field assert olunur; ucuz, sürətli və stabildir
A12: TC-API-101-011 | B12: fullName-də icazəli simvollar (Azərbaycan hərfləri, defis, apostrof, boşluq) | C12: GRAD-101 · POST /beneficiaries | D12: Medium | E12: Functional | F12: user1 ilə POST /auth/login edilib, token alınıb (base spec-də Authorization header) | G12: 1. POST /beneficiaries göndər | H12: fullName: "Şəhla Qasımova-O'Neil" | I12: 201; fullName olduğu kimi saxlanılır | J12: Gözlənilən nəticə alındı: 201; fullName olduğu kimi saxlanılır. Avtomat icra (Gauge + RestAssured, 02.10.2026), 3 icrada stabil | K12: PASS ✓ | L12: GRAD-101 AC-6 | M12: Automation | N12: Yes | O12: Pozitiv ekvivalent sinif: icazəli simvolların rədd edilməməsi yoxlanılır. Deterministik API testi: sandbox hər login-də təmiz mühit verir. Status + body sahələri + code assert olunur; hər relizdə icra olunmalıdır
... A170: TC-API-GEN-005 | B170: Rate limit (429 + Retry-After) | C170: Ümumi qaydalar (auth, sandbox, rate limit) | D170: Low | E170: Negative | F170: user1 ilə POST /auth/login edilib, token alınıb (base spec-də Authorization header) | G170: 1. Qısa müddətdə çoxlu sorğu göndər (CallMan Runner) | H170: Ardıcıl sorğular | I170: 429; Retry-After header mövcuddur | J170: İcra olunmadı: 429 almaq üçün paylaşılan test serverinə yüksək yük göndərmək lazımdır (digər istifadəçilərin işinə mane ola bilər), limitin dəyəri də sənədləşdirilməyib. Ayrıca mühitdə və ya müəllimin icazəsi ilə icra edilməlidir | K170: Blocked | L170: Ümumi qayda | M170: Manual | N170: No | O170: Paylaşılan serverə yük yaradır və digər tələbələrin testlərinə təsir edə bilər; bir dəfə nəzarətli şəkildə manual icra olunur

Sheet API Coverage
A1: Task | B1: Epic | C1: Endpoint | D1: Başlıq | E1: Prioritet | F1: Story Point | G1: AC sayı | H1: Test case sayı | I1: Automation | J1: Manual | K1: Regression
A2: GRAD-101 | B2: EPIC-1 | C2: POST /beneficiaries | D2: Yeni alıcı əlavə etmək | E2: High | F2: 5 | G2: 10 | H2: =COUNTIF('API Test Cases'!$C:$C,"GRAD-101 · POST /beneficiaries") -> 31 | I2: =COUNTIFS('API Test Cases'!$C:$C,"GRAD-101 · POST /beneficiaries",'API Test Cases'!$M:$M,"Automation") -> 30 | J2: =COUNTIFS('API Test Cases'!$C:$C,"GRAD-101 · POST /beneficiaries",'API Test Cases'!$M:$M,"Manual") -> 1 | K2: =COUNTIFS('API Test Cases'!$C:$C,"GRAD-101 · POST /beneficiaries",'API Test Cases'!$N:$N,"Yes") -> 30
A3: GRAD-102 | B3: EPIC-1 | C3: GET /beneficiaries | D3: Alıcılar siyahısı — axtarış, filtr, sıralama | E3: Medium | F3: 3 | G3: 7 | H3: =COUNTIF('API Test Cases'!$C:$C,"GRAD-102 · GET /beneficiaries") -> 15 | I3: =COUNTIFS('API Test Cases'!$C:$C,"GRAD-102 · GET /beneficiaries",'API Test Cases'!$M:$M,"Automation") -> 15 | J3: =COUNTIFS('API Test Cases'!$C:$C,"GRAD-102 · GET /beneficiaries",'API Test Cases'!$M:$M,"Manual") -> 0 | K3: =COUNTIFS('API Test Cases'!$C:$C,"GRAD-102 · GET /beneficiaries",'API Test Cases'!$N:$N,"Yes") -> 15
A4: GRAD-103 | B4: EPIC-1 | C4: DELETE /beneficiaries/{id} | D4: Alıcını silmək | E4: Medium | F4: 2 | G4: 4 | H4: =COUNTIF('API Test Cases'!$C:$C,"GRAD-103 · DELETE /beneficiaries/{id}") -> 7 | I4: =COUNTIFS('API Test Cases'!$C:$C,"GRAD-103 · DELETE /beneficiaries/{id}",'API Test Cases'!$M:$M,"Automation") -> 6 | J4: =COUNTIFS('API Test Cases'!$C:$C,"GRAD-103 · DELETE /beneficiaries/{id}",'API Test Cases'!$M:$M,"Manual") -> 1 | K4: =COUNTIFS('API Test Cases'!$C:$C,"GRAD-103 · DELETE /beneficiaries/{id}",'API Test Cases'!$N:$N,"Yes") -> 6
A5: GRAD-201 | B5: EPIC-2 | C5: POST /cards | D5: Virtual kart buraxmaq | E5: High | F5: 5 | G5: 8 | H5: =COUNTIF('API Test Cases'!$C:$C,"GRAD-201 · POST /cards") -> 21 | I5: =COUNTIFS('API Test Cases'!$C:$C,"GRAD-201 · POST /cards",'API Test Cases'!$M:$M,"Automation") -> 21 | J5: =COUNTIFS('API Test Cases'!$C:$C,"GRAD-201 · POST /cards",'API Test Cases'!$M:$M,"Manual") -> 0 | K5: =COUNTIFS('API Test Cases'!$C:$C,"GRAD-201 · POST /cards",'API Test Cases'!$N:$N,"Yes") -> 21
A6: GRAD-202 | B6: EPIC-2 | C6: GET /cards/{id} | D6: Kart məlumatına baxmaq | E6: Medium | F6: 2 | G6: 3 | H6: =COUNTIF('API Test Cases'!$C:$C,"GRAD-202 · GET /cards/{id}") -> 6 | I6: =COUNTIFS('API Test Cases'!$C:$C,"GRAD-202 · GET /cards/{id}",'API Test Cases'!$M:$M,"Automation") -> 5 | J6: =COUNTIFS('API Test Cases'!$C:$C,"GRAD-202 · GET /cards/{id}",'API Test Cases'!$M:$M,"Manual") -> 1 | K6: =COUNTIFS('API Test Cases'!$C:$C,"GRAD-202 · GET /cards/{id}",'API Test Cases'!$N:$N,"Yes") -> 5
A7: GRAD-203 | B7: EPIC-2 | C7: POST /cards/{id}/block | D7: Kartı bloklamaq / dondurmaq | E7: High | F7: 3 | G7: 7 | H7: =COUNTIF('API Test Cases'!$C:$C,"GRAD-203 · POST /cards/{id}/block") -> 19 | I7: =COUNTIFS('API Test Cases'!$C:$C,"GRAD-203 · POST /cards/{id}/block",'API Test Cases'!$M:$M,"Automation") -> 17 | J7: =COUNTIFS('API Test Cases'!$C:$C,"GRAD-203 · POST /cards/{id}/block",'API Test Cases'!$M:$M,"Manual") -> 2 | K7: =COUNTIFS('API Test Cases'!$C:$C,"GRAD-203 · POST /cards/{id}/block",'API Test Cases'!$N:$N,"Yes") -> 17
A8: GRAD-204 | B8: EPIC-2 | C8: POST /cards/{id}/unblock | D8: Dondurulmuş kartı açmaq | E8: Medium | F8: 2 | G8: 4 | H8: =COUNTIF('API Test Cases'!$C:$C,"GRAD-204 · POST /cards/{id}/unblock") -> 9 | I8: =COUNTIFS('API Test Cases'!$C:$C,"GRAD-204 · POST /cards/{id}/unblock",'API Test Cases'!$M:$M,"Automation") -> 8 | J8: =COUNTIFS('API Test Cases'!$C:$C,"GRAD-204 · POST /cards/{id}/unblock",'API Test Cases'!$M:$M,"Manual") -> 1 | K8: =COUNTIFS('API Test Cases'!$C:$C,"GRAD-204 · POST /cards/{id}/unblock",'API Test Cases'!$N:$N,"Yes") -> 8
